Workbook

Sheet WC
A1: Work code labor rates
A3: Shop Labor Rate | B3: 97 | D3: old rate 92 | E3: increase effective 1-1-26
A5: Work Code | B5: Description | C5: Hourly Rate | D5: Estimated Units | E5: Total
A6: 2010 | B6: Routing Labor | C6: =$B$3 -> 97 | D6: =(SUMIF('Freeform time and material'!$A$33:$A$44,A6,'Freeform time and material'!$G$33:$G$44)) + (SUMIF('Vinyl cutting'!$A$33:$A$44,A6,'Vinyl cutting'!$G$33:$G$44)) + (SUMIF('Vinyl cutting (2)'!$A$33:$A$44,A6,'Vinyl cutting (2)'!$G$33:$G$44)) + (SUMIF('Apply vinyl graphics'!$A$33:$A$44,A6,'Apply vinyl graphics'!$G$33:$G$44)) + (SUMIF('Apply vinyl graphics (2)'!$A$33:$A$44,A6,'Apply vinyl graphics (2)'!$G$33:$G$44)) + (SUMIF('Alum pan sign'!$A$33:$A$44,A6,'Alum pan sign'!$G$33:$G$44)) + (SUMIF('Alum pan sign (2)'!$A$33:$A$44,A6,'Alum pan sign (2)'!$G$33:$G$44)) + (SUMIF('Economy pan sign'!$A$33:$A$44,A6,'Economy pan sign'!$G$33:$G$44)) + (SUMIF('Post and panel sign'!$A$33:$A$44,A6,'Post and panel sign'!$G$33:$G$44)) + (SUMIF('Post and panel sign (2)'!$A$33:$A$44,A6,'Post and panel sign (2)'!$G$33:$G$44)) + (SUMIF('Flat panels only'!$A$33:$A$44,A6,'Flat panels only'!$G$33:$G$44)) + (SUMIF('Flat panels only (2)'!$A$33:$A$44,A6,'Flat panels only (2)'!$G$33:$G$44)) + (SUMIF('Routed panel shapes'!$A$34:$A$45,A6,'Routed panel shapes'!$G$34:$G$45)) + (SUMIF('Routed panel shapes (2)'!$A$34:$A$45,A6,'Routed panel shapes (2)'!$G$34:$G$45)) + (SUMIF('Routed face only'!$A$33:$A$44,A6,'Routed face only'!$G$33:$G$44)) + (SUMIF('Routed face only (2)'!$A$33:$A$44,A6,'Routed face only (2)'!$G$33:$G$44)) + (SUMIF('Routed alum faces letters'!$A$33:$A$44,A6,'Routed alum faces letters'!$G$33:$G$44)) + (SUMIF('Routed alum faces letters (2)'!$A$33:$A$44,A6,'Routed alum faces letters (2)'!$G$33:$G$44)) + (SUMIF('Routed push through acrylic'!$A$33:$A$44,A6,'Routed push through acrylic'!$G$33:$G$44)) + (SUMIF('Routed push through acrylic (2)'!$A$33:$A$44,A6,'Routed push through acrylic (2)'!$G$33:$G$44)) + (SUMIF('Sf routed cabinet'!$A$33:$A$44,A6,'Sf routed cabinet'!$G$33:$G$44)) + (SUMIF('Sf routed cabinet (2)'!$A$33:$A$44,A6,'Sf routed cabinet (2)'!$G$33:$G$44)) + (SUMIF('Df routed cabinet'!$A$33:$A$44,A6,'Df routed cabinet'!$G$33:$G$44)) + (SUMIF('Df routed cabinet (2)'!$A$33:$A$44,A6,'Df routed cabinet (2)'!$G$33:$G$44)) + (SUMIF('Sf acrylic cabinet'!$A$33:$A$44,A6,'Sf acrylic cabinet'!$G$33:$G$44)) + (SUMIF('Sf acrylic cabinet (2)'!$A$33:$A$44,A6,'Sf acrylic cabinet (2)'!$G$33:$G$44)) + (SUMIF('Economy Sf acrylic'!$A$33:$A$44,A6,'Economy Sf acrylic'!$G$33:$G$44)) + (SUMIF('Df acrylic cabinet'!$A$33:$A$44,A6,'Df acrylic cabinet'!$G$33:$G$44)) + (SUMIF('Df acrylic cabinet (2)'!$A$33:$A$44,A6,'Df acrylic cabinet (2)'!$G$33:$G$44)) + (SUMIF('Sf flex cabinet'!$A$33:$A$44,A6,'Sf flex cabinet'!$G$33:$G$44)) + (SUMIF('Sf flex cabinet (2)'!$A$33:$A$44,A6,'Sf flex cabinet (2)'!$G$33:$G$44)) + (SUMIF('Df flex cabinet'!$A$39:$A$50,A6,'Df flex cabinet'!$G$39:$G$50)) + (SUMIF('Df flex cabinet (2)'!$A$39:$A$50,A6,'Df flex cabinet (2)'!$G$39:$G$50)) + (SUMIF('Pole cover'!$A$33:$A$44,A6,'Pole cover'!$G$33:$G$44)) + (SUMIF('Pole cover (2)'!$A$33:$A$44,A6,'Pole cover (2)'!$G$33:$G$44)) + (SUMIF('Structural Steel Fab'!$A$33:$A$44,A6,'Structural Steel Fab'!$G$33:$G$44)) + (SUMIF(Reveal!$A$33:$A$44,A6,Reveal!$G$33:$G$44)) + (SUMIF('Reveal (2)'!$A$33:$A$44,A6,'Reveal (2)'!$G$33:$G$44)) + (SUMIF('Crown cove top'!$A$33:$A$44,A6,'Crown cove top'!$G$33:$G$44)) + (SUMIF('EMC assembly'!$A$33:$A$44,A6,'EMC assembly'!$G$33:$G$44)) + (SUMIF(Crating!$A$33:$A$44,A6,Crating!$G$33:$G$44)) + (SUMIF('LED wiring'!$A$33:$A$44,A6,'LED wiring'!$G$33:$G$44)) + (SUMIF('Changeable copy face'!$A$33:$A$44,A6,'Changeable copy face'!$G$33:$G$44)) + (SUMIF('Flex face assembly'!$A$33:$A$44,A6,'Flex face assembly'!$G$33:$G$44)) + (SUMIF('Routed face assembly'!$A$33:$A$44,A6,'Routed face assembly'!$G$33:$G$44)) + (SUMIF('Paint calculation'!$A$33:$A$44,A6,'Paint calculation'!$G$33:$G$44)) + (SUMIF('Trimcap letter face'!$A$33:$A$44,A6,'Trimcap letter face'!$G$33:$G$44)) + (SUMIF('Trimcap letter face (2)'!$A$33:$A$44,A6,'Trimcap letter face (2)'!$G$33:$G$44)) + (SUMIF('Channel letter fabrication'!$A$33:$A$44,A6,'Channel letter fabrication'!$G$33:$G$44)) + (SUMIF('Channel letter fabrication (2)'!$A$33:$A$44,A6,'Channel letter fabrication (2)'!$G$33:$G$44)) -> 28.25 | E6: =C6*D6 -> 2740.25
A7: 2011 | B7: Cabinet Metal Labor | C7: =$B$3 -> 97 | D7: =(SUMIF('Freeform time and material'!$A$33:$A$44,A7,'Freeform time and material'!$G$33:$G$44)) + (SUMIF('Vinyl cutting'!$A$33:$A$44,A7,'Vinyl cutting'!$G$33:$G$44)) + (SUMIF('Vinyl cutting (2)'!$A$33:$A$44,A7,'Vinyl cutting (2)'!$G$33:$G$44)) + (SUMIF('Apply vinyl graphics'!$A$33:$A$44,A7,'Apply vinyl graphics'!$G$33:$G$44)) + (SUMIF('Apply vinyl graphics (2)'!$A$33:$A$44,A7,'Apply vinyl graphics (2)'!$G$33:$G$44)) + (SUMIF('Alum pan sign'!$A$33:$A$44,A7,'Alum pan sign'!$G$33:$G$44)) + (SUMIF('Alum pan sign (2)'!$A$33:$A$44,A7,'Alum pan sign (2)'!$G$33:$G$44)) + (SUMIF('Economy pan sign'!$A$33:$A$44,A7,'Economy pan sign'!$G$33:$G$44)) + (SUMIF('Post and panel sign'!$A$33:$A$44,A7,'Post and panel sign'!$G$33:$G$44)) + (SUMIF('Post and panel sign (2)'!$A$33:$A$44,A7,'Post and panel sign (2)'!$G$33:$G$44)) + (SUMIF('Flat panels only'!$A$33:$A$44,A7,'Flat panels only'!$G$33:$G$44)) + (SUMIF('Flat panels only (2)'!$A$33:$A$44,A7,'Flat panels only (2)'!$G$33:$G$44)) + (SUMIF('Routed panel shapes'!$A$34:$A$45,A7,'Routed panel shapes'!$G$34:$G$45)) + (SUMIF('Routed panel shapes (2)'!$A$34:$A$45,A7,'Routed panel shapes (2)'!$G$34:$G$45)) + (SUMIF('Routed face only'!$A$33:$A$44,A7,'Routed face only'!$G$33:$G$44)) + (SUMIF('Routed face only (2)'!$A$33:$A$44,A7,'Routed face only (2)'!$G$33:$G$44)) + (SUMIF('Routed alum faces letters'!$A$33:$A$44,A7,'Routed alum faces letters'!$G$33:$G$44)) + (SUMIF('Routed alum faces letters (2)'!$A$33:$A$44,A7,'Routed alum faces letters (2)'!$G$33:$G$44)) + (SUMIF('Routed push through acrylic'!$A$33:$A$44,A7,'Routed push through acrylic'!$G$33:$G$44)) + (SUMIF('Routed push through acrylic (2)'!$A$33:$A$44,A7,'Routed push through acrylic (2)'!$G$33:$G$44)) + (SUMIF('Sf routed cabinet'!$A$33:$A$44,A7,'Sf routed cabinet'!$G$33:$G$44)) + (SUMIF('Sf routed cabinet (2)'!$A$33:$A$44,A7,'Sf routed cabinet (2)'!$G$33:$G$44)) + (SUMIF('Df routed cabinet'!$A$33:$A$44,A7,'Df routed cabinet'!$G$33:$G$44)) + (SUMIF('Df routed cabinet (2)'!$A$33:$A$44,A7,'Df routed cabinet (2)'!$G$33:$G$44)) + (SUMIF('Sf acrylic cabinet'!$A$33:$A$44,A7,'Sf acrylic cabinet'!$G$33:$G$44)) + (SUMIF('Sf acrylic cabinet (2)'!$A$33:$A$44,A7,'Sf acrylic cabinet (2)'!$G$33:$G$44)) + (SUMIF('Economy Sf acrylic'!$A$33:$A$44,A7,'Economy Sf acrylic'!$G$33:$G$44)) + (SUMIF('Df acrylic cabinet'!$A$33:$A$44,A7,'Df acrylic cabinet'!$G$33:$G$44)) + (SUMIF('Df acrylic cabinet (2)'!$A$33:$A$44,A7,'Df acrylic cabinet (2)'!$G$33:$G$44)) + (SUMIF('Sf flex cabinet'!$A$33:$A$44,A7,'Sf flex cabinet'!$G$33:$G$44)) + (SUMIF('Sf flex cabinet (2)'!$A$33:$A$44,A7,'Sf flex cabinet (2)'!$G$33:$G$44)) + (SUMIF('Df flex cabinet'!$A$39:$A$50,A7,'Df flex cabinet'!$G$39:$G$50)) + (SUMIF('Df flex cabinet (2)'!$A$39:$A$50,A7,'Df flex cabinet (2)'!$G$39:$G$50)) + (SUMIF('Pole cover'!$A$33:$A$44,A7,'Pole cover'!$G$33:$G$44)) + (SUMIF('Pole cover (2)'!$A$33:$A$44,A7,'Pole cover (2)'!$G$33:$G$44)) + (SUMIF('Structural Steel Fab'!$A$33:$A$44,A7,'Structural Steel Fab'!$G$33:$G$44)) + (SUMIF(Reveal!$A$33:$A$44,A7,Reveal!$G$33:$G$44)) + (SUMIF('Reveal (2)'!$A$33:$A$44,A7,'Reveal (2)'!$G$33:$G$44)) + (SUMIF('Crown cove top'!$A$33:$A$44,A7,'Crown cove top'!$G$33:$G$44)) + (SUMIF('EMC assembly'!$A$33:$A$44,A7,'EMC assembly'!$G$33:$G$44)) + (SUMIF(Crating!$A$33:$A$44,A7,Crating!$G$33:$G$44)) + (SUMIF('LED wiring'!$A$33:$A$44,A7,'LED wiring'!$G$33:$G$44)) + (SUMIF('Changeable copy face'!$A$33:$A$44,A7,'Changeable copy face'!$G$33:$G$44)) + (SUMIF('Flex face assembly'!$A$33:$A$44,A7,'Flex face assembly'!$G$33:$G$44)) + (SUMIF('Routed face assembly'!$A$33:$A$44,A7,'Routed face assembly'!$G$33:$G$44)) + (SUMIF('Paint calculation'!$A$33:$A$44,A7,'Paint calculation'!$G$33:$G$44)) + (SUMIF('Trimcap letter face'!$A$33:$A$44,A7,'Trimcap letter face'!$G$33:$G$44)) + (SUMIF('Trimcap letter face (2)'!$A$33:$A$44,A7,'Trimcap letter face (2)'!$G$33:$G$44)) + (SUMIF('Channel letter fabrication'!$A$33:$A$44,A7,'Channel letter fabrication'!$G$33:$G$44)) + (SUMIF('Channel letter fabrication (2)'!$A$33:$A$44,A7,'Channel letter fabrication (2)'!$G$33:$G$44)) -> 57.5625 | E7: =C7*D7 -> 5583.5625
A8: 2014 | B8: Letter Metal Labor | C8: =$B$3 -> 97 | D8: =(SUMIF('Freeform time and material'!$A$33:$A$44,A8,'Freeform time and material'!$G$33:$G$44)) + (SUMIF('Vinyl cutting'!$A$33:$A$44,A8,'Vinyl cutting'!$G$33:$G$44)) + (SUMIF('Vinyl cutting (2)'!$A$33:$A$44,A8,'Vinyl cutting (2)'!$G$33:$G$44)) + (SUMIF('Apply vinyl graphics'!$A$33:$A$44,A8,'Apply vinyl graphics'!$G$33:$G$44)) + (SUMIF('Apply vinyl graphics (2)'!$A$33:$A$44,A8,'Apply vinyl graphics (2)'!$G$33:$G$44)) + (SUMIF('Alum pan sign'!$A$33:$A$44,A8,'Alum pan sign'!$G$33:$G$44)) + (SUMIF('Alum pan sign (2)'!$A$33:$A$44,A8,'Alum pan sign (2)'!$G$33:$G$44)) + (SUMIF('Economy pan sign'!$A$33:$A$44,A8,'Economy pan sign'!$G$33:$G$44)) + (SUMIF('Post and panel sign'!$A$33:$A$44,A8,'Post and panel sign'!$G$33:$G$44)) + (SUMIF('Post and panel sign (2)'!$A$33:$A$44,A8,'Post and panel sign (2)'!$G$33:$G$44)) + (SUMIF('Flat panels only'!$A$33:$A$44,A8,'Flat panels only'!$G$33:$G$44)) + (SUMIF('Flat panels only (2)'!$A$33:$A$44,A8,'Flat panels only (2)'!$G$33:$G$44)) + (SUMIF('Routed panel shapes'!$A$34:$A$45,A8,'Routed panel shapes'!$G$34:$G$45)) + (SUMIF('Routed panel shapes (2)'!$A$34:$A$45,A8,'Routed panel shapes (2)'!$G$34:$G$45)) + (SUMIF('Routed face only'!$A$33:$A$44,A8,'Routed face only'!$G$33:$G$44)) + (SUMIF('Routed face only (2)'!$A$33:$A$44,A8,'Routed face only (2)'!$G$33:$G$44)) + (SUMIF('Routed alum faces letters'!$A$33:$A$44,A8,'Routed alum faces letters'!$G$33:$G$44)) + (SUMIF('Routed alum faces letters (2)'!$A$33:$A$44,A8,'Routed alum faces letters (2)'!$G$33:$G$44)) + (SUMIF('Routed push through acrylic'!$A$33:$A$44,A8,'Routed push through acrylic'!$G$33:$G$44)) + (SUMIF('Routed push through acrylic (2)'!$A$33:$A$44,A8,'Routed push through acrylic (2)'!$G$33:$G$44)) + (SUMIF('Sf routed cabinet'!$A$33:$A$44,A8,'Sf routed cabinet'!$G$33:$G$44)) + (SUMIF('Sf routed cabinet (2)'!$A$33:$A$44,A8,'Sf routed cabinet (2)'!$G$33:$G$44)) + (SUMIF('Df routed cabinet'!$A$33:$A$44,A8,'Df routed cabinet'!$G$33:$G$44)) + (SUMIF('Df routed cabinet (2)'!$A$33:$A$44,A8,'Df routed cabinet (2)'!$G$33:$G$44)) + (SUMIF('Sf acrylic cabinet'!$A$33:$A$44,A8,'Sf acrylic cabinet'!$G$33:$G$44)) + (SUMIF('Sf acrylic cabinet (2)'!$A$33:$A$44,A8,'Sf acrylic cabinet (2)'!$G$33:$G$44)) + (SUMIF('Economy Sf acrylic'!$A$33:$A$44,A8,'Economy Sf acrylic'!$G$33:$G$44)) + (SUMIF('Df acrylic cabinet'!$A$33:$A$44,A8,'Df acrylic cabinet'!$G$33:$G$44)) + (SUMIF('Df acrylic cabinet (2)'!$A$33:$A$44,A8,'Df acrylic cabinet (2)'!$G$33:$G$44)) + (SUMIF('Sf flex cabinet'!$A$33:$A$44,A8,'Sf flex cabinet'!$G$33:$G$44)) + (SUMIF('Sf flex cabinet (2)'!$A$33:$A$44,A8,'Sf flex cabinet (2)'!$G$33:$G$44)) + (SUMIF('Df flex cabinet'!$A$39:$A$50,A8,'Df flex cabinet'!$G$39:$G$50)) + (SUMIF('Df flex cabinet (2)'!$A$39:$A$50,A8,'Df flex cabinet (2)'!$G$39:$G$50)) + (SUMIF('Pole cover'!$A$33:$A$44,A8,'Pole cover'!$G$33:$G$44)) + (SUMIF('Pole cover (2)'!$A$33:$A$44,A8,'Pole cover (2)'!$G$33:$G$44)) + (SUMIF('Structural Steel Fab'!$A$33:$A$44,A8,'Structural Steel Fab'!$G$33:$G$44)) + (SUMIF(Reveal!$A$33:$A$44,A8,Reveal!$G$33:$G$44)) + (SUMIF('Reveal (2)'!$A$33:$A$44,A8,'Reveal (2)'!$G$33:$G$44)) + (SUMIF('Crown cove top'!$A$33:$A$44,A8,'Crown cove top'!$G$33:$G$44)) + (SUMIF('EMC assembly'!$A$33:$A$44,A8,'EMC assembly'!$G$33:$G$44)) + (SUMIF(Crating!$A$33:$A$44,A8,Crating!$G$33:$G$44)) + (SUMIF('LED wiring'!$A$33:$A$44,A8,'LED wiring'!$G$33:$G$44)) + (SUMIF('Changeable copy face'!$A$33:$A$44,A8,'Changeable copy face'!$G$33:$G$44)) + (SUMIF('Flex face assembly'!$A$33:$A$44,A8,'Flex face assembly'!$G$33:$G$44)) + (SUMIF('Routed face assembly'!$A$33:$A$44,A8,'Routed face assembly'!$G$33:$G$44)) + (SUMIF('Paint calculation'!$A$33:$A$44,A8,'Paint calculation'!$G$33:$G$44)) + (SUMIF('Trimcap letter face'!$A$33:$A$44,A8,'Trimcap letter face'!$G$33:$G$44)) + (SUMIF('Trimcap letter face (2)'!$A$33:$A$44,A8,'Trimcap letter face (2)'!$G$33:$G$44)) + (SUMIF('Channel letter fabrication'!$A$33:$A$44,A8,'Channel letter fabrication'!$G$33:$G$44)) + (SUMIF('Channel letter fabrication (2)'!$A$33:$A$44,A8,'Channel letter fabrication (2)'!$G$33:$G$44)) -> 0 | E8: =C8*D8 -> 0
A9: 2016 | B9: Structural Steel Metal Labor | C9: =$B$3 -> 97 | D9: =(SUMIF('Freeform time and material'!$A$33:$A$44,A9,'Freeform time and material'!$G$33:$G$44)) + (SUMIF('Vinyl cutting'!$A$33:$A$44,A9,'Vinyl cutting'!$G$33:$G$44)) + (SUMIF('Vinyl cutting (2)'!$A$33:$A$44,A9,'Vinyl cutting (2)'!$G$33:$G$44)) + (SUMIF('Apply vinyl graphics'!$A$33:$A$44,A9,'Apply vinyl graphics'!$G$33:$G$44)) + (SUMIF('Apply vinyl graphics (2)'!$A$33:$A$44,A9,'Apply vinyl graphics (2)'!$G$33:$G$44)) + (SUMIF('Alum pan sign'!$A$33:$A$44,A9,'Alum pan sign'!$G$33:$G$44)) + (SUMIF('Alum pan sign (2)'!$A$33:$A$44,A9,'Alum pan sign (2)'!$G$33:$G$44)) + (SUMIF('Economy pan sign'!$A$33:$A$44,A9,'Economy pan sign'!$G$33:$G$44)) + (SUMIF('Post and panel sign'!$A$33:$A$44,A9,'Post and panel sign'!$G$33:$G$44)) + (SUMIF('Post and panel sign (2)'!$A$33:$A$44,A9,'Post and panel sign (2)'!$G$33:$G$44)) + (SUMIF('Flat panels only'!$A$33:$A$44,A9,'Flat panels only'!$G$33:$G$44)) + (SUMIF('Flat panels only (2)'!$A$33:$A$44,A9,'Flat panels only (2)'!$G$33:$G$44)) + (SUMIF('Routed panel shapes'!$A$34:$A$45,A9,'Routed panel shapes'!$G$34:$G$45)) + (SUMIF('Routed panel shapes (2)'!$A$34:$A$45,A9,'Routed panel shapes (2)'!$G$34:$G$45)) + (SUMIF('Routed face only'!$A$33:$A$44,A9,'Routed face only'!$G$33:$G$44)) + (SUMIF('Routed face only (2)'!$A$33:$A$44,A9,'Routed face only (2)'!$G$33:$G$44)) + (SUMIF('Routed alum faces letters'!$A$33:$A$44,A9,'Routed alum faces letters'!$G$33:$G$44)) + (SUMIF('Routed alum faces letters (2)'!$A$33:$A$44,A9,'Routed alum faces letters (2)'!$G$33:$G$44)) + (SUMIF('Routed push through acrylic'!$A$33:$A$44,A9,'Routed push through acrylic'!$G$33:$G$44)) + (SUMIF('Routed push through acrylic (2)'!$A$33:$A$44,A9,'Routed push through acrylic (2)'!$G$33:$G$44)) + (SUMIF('Sf routed cabinet'!$A$33:$A$44,A9,'Sf routed cabinet'!$G$33:$G$44)) + (SUMIF('Sf routed cabinet (2)'!$A$33:$A$44,A9,'Sf routed cabinet (2)'!$G$33:$G$44)) + (SUMIF('Df routed cabinet'!$A$33:$A$44,A9,'Df routed cabinet'!$G$33:$G$44)) + (SUMIF('Df routed cabinet (2)'!$A$33:$A$44,A9,'Df routed cabinet (2)'!$G$33:$G$44)) + (SUMIF('Sf acrylic cabinet'!$A$33:$A$44,A9,'Sf acrylic cabinet'!$G$33:$G$44)) + (SUMIF('Sf acrylic cabinet (2)'!$A$33:$A$44,A9,'Sf acrylic cabinet (2)'!$G$33:$G$44)) + (SUMIF('Economy Sf acrylic'!$A$33:$A$44,A9,'Economy Sf acrylic'!$G$33:$G$44)) + (SUMIF('Df acrylic cabinet'!$A$33:$A$44,A9,'Df acrylic cabinet'!$G$33:$G$44)) + (SUMIF('Df acrylic cabinet (2)'!$A$33:$A$44,A9,'Df acrylic cabinet (2)'!$G$33:$G$44)) + (SUMIF('Sf flex cabinet'!$A$33:$A$44,A9,'Sf flex cabinet'!$G$33:$G$44)) + (SUMIF('Sf flex cabinet (2)'!$A$33:$A$44,A9,'Sf flex cabinet (2)'!$G$33:$G$44)) + (SUMIF('Df flex cabinet'!$A$39:$A$50,A9,'Df flex cabinet'!$G$39:$G$50)) + (SUMIF('Df flex cabinet (2)'!$A$39:$A$50,A9,'Df flex cabinet (2)'!$G$39:$G$50)) + (SUMIF('Pole cover'!$A$33:$A$44,A9,'Pole cover'!$G$33:$G$44)) + (SUMIF('Pole cover (2)'!$A$33:$A$44,A9,'Pole cover (2)'!$G$33:$G$44)) + (SUMIF('Structural Steel Fab'!$A$33:$A$44,A9,'Structural Steel Fab'!$G$33:$G$44)) + (SUMIF(Reveal!$A$33:$A$44,A9,Reveal!$G$33:$G$44)) + (SUMIF('Reveal (2)'!$A$33:$A$44,A9,'Reveal (2)'!$G$33:$G$44)) + (SUMIF('Crown cove top'!$A$33:$A$44,A9,'Crown cove top'!$G$33:$G$44)) + (SUMIF('EMC assembly'!$A$33:$A$44,A9,'EMC assembly'!$G$33:$G$44)) + (SUMIF(Crating!$A$33:$A$44,A9,Crating!$G$33:$G$44)) + (SUMIF('LED wiring'!$A$33:$A$44,A9,'LED wiring'!$G$33:$G$44)) + (SUMIF('Changeable copy face'!$A$33:$A$44,A9,'Changeable copy face'!$G$33:$G$44)) + (SUMIF('Flex face assembly'!$A$33:$A$44,A9,'Flex face assembly'!$G$33:$G$44)) + (SUMIF('Routed face assembly'!$A$33:$A$44,A9,'Routed face assembly'!$G$33:$G$44)) + (SUMIF('Paint calculation'!$A$33:$A$44,A9,'Paint calculation'!$G$33:$G$44)) + (SUMIF('Trimcap letter face'!$A$33:$A$44,A9,'Trimcap letter face'!$G$33:$G$44)) + (SUMIF('Trimcap letter face (2)'!$A$33:$A$44,A9,'Trimcap letter face (2)'!$G$33:$G$44)) + (SUMIF('Channel letter fabrication'!$A$33:$A$44,A9,'Channel letter fabrication'!$G$33:$G$44)) + (SUMIF('Channel letter fabrication (2)'!$A$33:$A$44,A9,'Channel letter fabrication (2)'!$G$33:$G$44)) -> 4 | E9: =C9*D9 -> 388
A10: 2099 | B10: Rework Metal Labor | C10: =$B$3 -> 97 | D10: =(SUMIF('Freeform time and material'!$A$33:$A$44,A10,'Freeform time and material'!$G$33:$G$44)) + (SUMIF('Vinyl cutting'!$A$33:$A$44,A10,'Vinyl cutting'!$G$33:$G$44)) + (SUMIF('Vinyl cutting (2)'!$A$33:$A$44,A10,'Vinyl cutting (2)'!$G$33:$G$44)) + (SUMIF('Apply vinyl graphics'!$A$33:$A$44,A10,'Apply vinyl graphics'!$G$33:$G$44)) + (SUMIF('Apply vinyl graphics (2)'!$A$33:$A$44,A10,'Apply vinyl graphics (2)'!$G$33:$G$44)) + (SUMIF('Alum pan sign'!$A$33:$A$44,A10,'Alum pan sign'!$G$33:$G$44)) + (SUMIF('Alum pan sign (2)'!$A$33:$A$44,A10,'Alum pan sign (2)'!$G$33:$G$44)) + (SUMIF('Economy pan sign'!$A$33:$A$44,A10,'Economy pan sign'!$G$33:$G$44)) + (SUMIF('Post and panel sign'!$A$33:$A$44,A10,'Post and panel sign'!$G$33:$G$44)) + (SUMIF('Post and panel sign (2)'!$A$33:$A$44,A10,'Post and panel sign (2)'!$G$33:$G$44)) + (SUMIF('Flat panels only'!$A$33:$A$44,A10,'Flat panels only'!$G$33:$G$44)) + (SUMIF('Flat panels only (2)'!$A$33:$A$44,A10,'Flat panels only (2)'!$G$33:$G$44)) + (SUMIF('Routed panel shapes'!$A$34:$A$45,A10,'Routed panel shapes'!$G$34:$G$45)) + (SUMIF('Routed panel shapes (2)'!$A$34:$A$45,A10,'Routed panel shapes (2)'!$G$34:$G$45)) + (SUMIF('Routed face only'!$A$33:$A$44,A10,'Routed face only'!$G$33:$G$44)) + (SUMIF('Routed face only (2)'!$A$33:$A$44,A10,'Routed face only (2)'!$G$33:$G$44)) + (SUMIF('Routed alum faces letters'!$A$33:$A$44,A10,'Routed alum faces letters'!$G$33:$G$44)) + (SUMIF('Routed alum faces letters (2)'!$A$33:$A$44,A10,'Routed alum faces letters (2)'!$G$33:$G$44)) + (SUMIF('Routed push through acrylic'!$A$33:$A$44,A10,'Routed push through acrylic'!$G$33:$G$44)) + (SUMIF('Routed push through acrylic (2)'!$A$33:$A$44,A10,'Routed push through acrylic (2)'!$G$33:$G$44)) + (SUMIF('Sf routed cabinet'!$A$33:$A$44,A10,'Sf routed cabinet'!$G$33:$G$44)) + (SUMIF('Sf routed cabinet (2)'!$A$33:$A$44,A10,'Sf routed cabinet (2)'!$G$33:$G$44)) + (SUMIF('Df routed cabinet'!$A$33:$A$44,A10,'Df routed cabinet'!$G$33:$G$44)) + (SUMIF('Df routed cabinet (2)'!$A$33:$A$44,A10,'Df routed cabinet (2)'!$G$33:$G$44)) + (SUMIF('Sf acrylic cabinet'!$A$33:$A$44,A10,'Sf acrylic cabinet'!$G$33:$G$44)) + (SUMIF('Sf acrylic cabinet (2)'!$A$33:$A$44,A10,'Sf acrylic cabinet (2)'!$G$33:$G$44)) + (SUMIF('Economy Sf acrylic'!$A$33:$A$44,A10,'Economy Sf acrylic'!$G$33:$G$44)) + (SUMIF('Df acrylic cabinet'!$A$33:$A$44,A10,'Df acrylic cabinet'!$G$33:$G$44)) + (SUMIF('Df acrylic cabinet (2)'!$A$33:$A$44,A10,'Df acrylic cabinet (2)'!$G$33:$G$44)) + (SUMIF('Sf flex cabinet'!$A$33:$A$44,A10,'Sf flex cabinet'!$G$33:$G$44)) + (SUMIF('Sf flex cabinet (2)'!$A$33:$A$44,A10,'Sf flex cabinet (2)'!$G$33:$G$44)) + (SUMIF('Df flex cabinet'!$A$39:$A$50,A10,'Df flex cabinet'!$G$39:$G$50)) + (SUMIF('Df flex cabinet (2)'!$A$39:$A$50,A10,'Df flex cabinet (2)'!$G$39:$G$50)) + (SUMIF('Pole cover'!$A$33:$A$44,A10,'Pole cover'!$G$33:$G$44)) + (SUMIF('Pole cover (2)'!$A$33:$A$44,A10,'Pole cover (2)'!$G$33:$G$44)) + (SUMIF('Structural Steel Fab'!$A$33:$A$44,A10,'Structural Steel Fab'!$G$33:$G$44)) + (SUMIF(Reveal!$A$33:$A$44,A10,Reveal!$G$33:$G$44)) + (SUMIF('Reveal (2)'!$A$33:$A$44,A10,'Reveal (2)'!$G$33:$G$44)) + (SUMIF('Crown cove top'!$A$33:$A$44,A10,'Crown cove top'!$G$33:$G$44)) + (SUMIF('EMC assembly'!$A$33:$A$44,A10,'EMC assembly'!$G$33:$G$44)) + (SUMIF(Crating!$A$33:$A$44,A10,Crating!$G$33:$G$44)) + (SUMIF('LED wiring'!$A$33:$A$44,A10,'LED wiring'!$G$33:$G$44)) + (SUMIF('Changeable copy face'!$A$33:$A$44,A10,'Changeable copy face'!$G$33:$G$44)) + (SUMIF('Flex face assembly'!$A$33:$A$44,A10,'Flex face assembly'!$G$33:$G$44)) + (SUMIF('Routed face assembly'!$A$33:$A$44,A10,'Routed face assembly'!$G$33:$G$44)) + (SUMIF('Paint calculation'!$A$33:$A$44,A10,'Paint calculation'!$G$33:$G$44)) + (SUMIF('Trimcap letter face'!$A$33:$A$44,A10,'Trimcap letter face'!$G$33:$G$44)) + (SUMIF('Trimcap letter face (2)'!$A$33:$A$44,A10,'Trimcap letter face (2)'!$G$33:$G$44)) + (SUMIF('Channel letter fabrication'!$A$33:$A$44,A10,'Channel letter fabrication'!$G$33:$G$44)) + (SUMIF('Channel letter fabrication (2)'!$A$33:$A$44,A10,'Channel letter fabrication (2)'!$G$33:$G$44)) -> 0 | E10: =C10*D10 -> 0
A11: 2110 | B11: Paint Prep Labor | C11: =$B$3 -> 97 | D11: =(SUMIF('Freeform time and material'!$A$33:$A$44,A11,'Freeform time and material'!$G$33:$G$44)) + (SUMIF('Vinyl cutting'!$A$33:$A$44,A11,'Vinyl cutting'!$G$33:$G$44)) + (SUMIF('Vinyl cutting (2)'!$A$33:$A$44,A11,'Vinyl cutting (2)'!$G$33:$G$44)) + (SUMIF('Apply vinyl graphics'!$A$33:$A$44,A11,'Apply vinyl graphics'!$G$33:$G$44)) + (SUMIF('Apply vinyl graphics (2)'!$A$33:$A$44,A11,'Apply vinyl graphics (2)'!$G$33:$G$44)) + (SUMIF('Alum pan sign'!$A$33:$A$44,A11,'Alum pan sign'!$G$33:$G$44)) + (SUMIF('Alum pan sign (2)'!$A$33:$A$44,A11,'Alum pan sign (2)'!$G$33:$G$44)) + (SUMIF('Economy pan sign'!$A$33:$A$44,A11,'Economy pan sign'!$G$33:$G$44)) + (SUMIF('Post and panel sign'!$A$33:$A$44,A11,'Post and panel sign'!$G$33:$G$44)) + (SUMIF('Post and panel sign (2)'!$A$33:$A$44,A11,'Post and panel sign (2)'!$G$33:$G$44)) + (SUMIF('Flat panels only'!$A$33:$A$44,A11,'Flat panels only'!$G$33:$G$44)) + (SUMIF('Flat panels only (2)'!$A$33:$A$44,A11,'Flat panels only (2)'!$G$33:$G$44)) + (SUMIF('Routed panel shapes'!$A$34:$A$45,A11,'Routed panel shapes'!$G$34:$G$45)) + (SUMIF('Routed panel shapes (2)'!$A$34:$A$45,A11,'Routed panel shapes (2)'!$G$34:$G$45)) + (SUMIF('Routed face only'!$A$33:$A$44,A11,'Routed face only'!$G$33:$G$44)) + (SUMIF('Routed face only (2)'!$A$33:$A$44,A11,'Routed face only (2)'!$G$33:$G$44)) + (SUMIF('Routed alum faces letters'!$A$33:$A$44,A11,'Routed alum faces letters'!$G$33:$G$44)) + (SUMIF('Routed alum faces letters (2)'!$A$33:$A$44,A11,'Routed alum faces letters (2)'!$G$33:$G$44)) + (SUMIF('Routed push through acrylic'!$A$33:$A$44,A11,'Routed push through acrylic'!$G$33:$G$44)) + (SUMIF('Routed push through acrylic (2)'!$A$33:$A$44,A11,'Routed push through acrylic (2)'!$G$33:$G$44)) + (SUMIF('Sf routed cabinet'!$A$33:$A$44,A11,'Sf routed cabinet'!$G$33:$G$44)) + (SUMIF('Sf routed cabinet (2)'!$A$33:$A$44,A11,'Sf routed cabinet (2)'!$G$33:$G$44)) + (SUMIF('Df routed cabinet'!$A$33:$A$44,A11,'Df routed cabinet'!$G$33:$G$44)) + (SUMIF('Df routed cabinet (2)'!$A$33:$A$44,A11,'Df routed cabinet (2)'!$G$33:$G$44)) + (SUMIF('Sf acrylic cabinet'!$A$33:$A$44,A11,'Sf acrylic cabinet'!$G$33:$G$44)) + (SUMIF('Sf acrylic cabinet (2)'!$A$33:$A$44,A11,'Sf acrylic cabinet (2)'!$G$33:$G$44)) + (SUMIF('Economy Sf acrylic'!$A$33:$A$44,A11,'Economy Sf acrylic'!$G$33:$G$44)) + (SUMIF('Df acrylic cabinet'!$A$33:$A$44,A11,'Df acrylic cabinet'!$G$33:$G$44)) + (SUMIF('Df acrylic cabinet (2)'!$A$33:$A$44,A11,'Df acrylic cabinet (2)'!$G$33:$G$44)) + (SUMIF('Sf flex cabinet'!$A$33:$A$44,A11,'Sf flex cabinet'!$G$33:$G$44)) + (SUMIF('Sf flex cabinet (2)'!$A$33:$A$44,A11,'Sf flex cabinet (2)'!$G$33:$G$44)) + (SUMIF('Df flex cabinet'!$A$39:$A$50,A11,'Df flex cabinet'!$G$39:$G$50)) + (SUMIF('Df flex cabinet (2)'!$A$39:$A$50,A11,'Df flex cabinet (2)'!$G$39:$G$50)) + (SUMIF('Pole cover'!$A$33:$A$44,A11,'Pole cover'!$G$33:$G$44)) + (SUMIF('Pole cover (2)'!$A$33:$A$44,A11,'Pole cover (2)'!$G$33:$G$44)) + (SUMIF('Structural Steel Fab'!$A$33:$A$44,A11,'Structural Steel Fab'!$G$33:$G$44)) + (SUMIF(Reveal!$A$33:$A$44,A11,Reveal!$G$33:$G$44)) + (SUMIF('Reveal (2)'!$A$33:$A$44,A11,'Reveal (2)'!$G$33:$G$44)) + (SUMIF('Crown cove top'!$A$33:$A$44,A11,'Crown cove top'!$G$33:$G$44)) + (SUMIF('EMC assembly'!$A$33:$A$44,A11,'EMC assembly'!$G$33:$G$44)) + (SUMIF(Crating!$A$33:$A$44,A11,Crating!$G$33:$G$44)) + (SUMIF('LED wiring'!$A$33:$A$44,A11,'LED wiring'!$G$33:$G$44)) + (SUMIF('Changeable copy face'!$A$33:$A$44,A11,'Changeable copy face'!$G$33:$G$44)) + (SUMIF('Flex face assembly'!$A$33:$A$44,A11,'Flex face assembly'!$G$33:$G$44)) + (SUMIF('Routed face assembly'!$A$33:$A$44,A11,'Routed face assembly'!$G$33:$G$44)) + (SUMIF('Paint calculation'!$A$33:$A$44,A11,'Paint calculation'!$G$33:$G$44)) + (SUMIF('Trimcap letter face'!$A$33:$A$44,A11,'Trimcap letter face'!$G$33:$G$44)) + (SUMIF('Trimcap letter face (2)'!$A$33:$A$44,A11,'Trimcap letter face (2)'!$G$33:$G$44)) + (SUMIF('Channel letter fabrication'!$A$33:$A$44,A11,'Channel letter fabrication'!$G$33:$G$44)) + (SUMIF('Channel letter fabrication (2)'!$A$33:$A$44,A11,'Channel letter fabrication (2)'!$G$33:$G$44)) -> 25.5 | E11: =C11*D11 -> 2473.5
A12: 2112 | B12: Paint Cabinet & Letters Labor | C12: =$B$3 -> 97 | D12: =(SUMIF('Freeform time and material'!$A$33:$A$44,A12,'Freeform time and material'!$G$33:$G$44)) + (SUMIF('Vinyl cutting'!$A$33:$A$44,A12,'Vinyl cutting'!$G$33:$G$44)) + (SUMIF('Vinyl cutting (2)'!$A$33:$A$44,A12,'Vinyl cutting (2)'!$G$33:$G$44)) + (SUMIF('Apply vinyl graphics'!$A$33:$A$44,A12,'Apply vinyl graphics'!$G$33:$G$44)) + (SUMIF('Apply vinyl graphics (2)'!$A$33:$A$44,A12,'Apply vinyl graphics (2)'!$G$33:$G$44)) + (SUMIF('Alum pan sign'!$A$33:$A$44,A12,'Alum pan sign'!$G$33:$G$44)) + (SUMIF('Alum pan sign (2)'!$A$33:$A$44,A12,'Alum pan sign (2)'!$G$33:$G$44)) + (SUMIF('Economy pan sign'!$A$33:$A$44,A12,'Economy pan sign'!$G$33:$G$44)) + (SUMIF('Post and panel sign'!$A$33:$A$44,A12,'Post and panel sign'!$G$33:$G$44)) + (SUMIF('Post and panel sign (2)'!$A$33:$A$44,A12,'Post and panel sign (2)'!$G$33:$G$44)) + (SUMIF('Flat panels only'!$A$33:$A$44,A12,'Flat panels only'!$G$33:$G$44)) + (SUMIF('Flat panels only (2)'!$A$33:$A$44,A12,'Flat panels only (2)'!$G$33:$G$44)) + (SUMIF('Routed panel shapes'!$A$34:$A$45,A12,'Routed panel shapes'!$G$34:$G$45)) + (SUMIF('Routed panel shapes (2)'!$A$34:$A$45,A12,'Routed panel shapes (2)'!$G$34:$G$45)) + (SUMIF('Routed face only'!$A$33:$A$44,A12,'Routed face only'!$G$33:$G$44)) + (SUMIF('Routed face only (2)'!$A$33:$A$44,A12,'Routed face only (2)'!$G$33:$G$44)) + (SUMIF('Routed alum faces letters'!$A$33:$A$44,A12,'Routed alum faces letters'!$G$33:$G$44)) + (SUMIF('Routed alum faces letters (2)'!$A$33:$A$44,A12,'Routed alum faces letters (2)'!$G$33:$G$44)) + (SUMIF('Routed push through acrylic'!$A$33:$A$44,A12,'Routed push through acrylic'!$G$33:$G$44)) + (SUMIF('Routed push through acrylic (2)'!$A$33:$A$44,A12,'Routed push through acrylic (2)'!$G$33:$G$44)) + (SUMIF('Sf routed cabinet'!$A$33:$A$44,A12,'Sf routed cabinet'!$G$33:$G$44)) + (SUMIF('Sf routed cabinet (2)'!$A$33:$A$44,A12,'Sf routed cabinet (2)'!$G$33:$G$44)) + (SUMIF('Df routed cabinet'!$A$33:$A$44,A12,'Df routed cabinet'!$G$33:$G$44)) + (SUMIF('Df routed cabinet (2)'!$A$33:$A$44,A12,'Df routed cabinet (2)'!$G$33:$G$44)) + (SUMIF('Sf acrylic cabinet'!$A$33:$A$44,A12,'Sf acrylic cabinet'!$G$33:$G$44)) + (SUMIF('Sf acrylic cabinet (2)'!$A$33:$A$44,A12,'Sf acrylic cabinet (2)'!$G$33:$G$44)) + (SUMIF('Economy Sf acrylic'!$A$33:$A$44,A12,'Economy Sf acrylic'!$G$33:$G$44)) + (SUMIF('Df acrylic cabinet'!$A$33:$A$44,A12,'Df acrylic cabinet'!$G$33:$G$44)) + (SUMIF('Df acrylic cabinet (2)'!$A$33:$A$44,A12,'Df acrylic cabinet (2)'!$G$33:$G$44)) + (SUMIF('Sf flex cabinet'!$A$33:$A$44,A12,'Sf flex cabinet'!$G$33:$G$44)) + (SUMIF('Sf flex cabinet (2)'!$A$33:$A$44,A12,'Sf flex cabinet (2)'!$G$33:$G$44)) + (SUMIF('Df flex cabinet'!$A$39:$A$50,A12,'Df flex cabinet'!$G$39:$G$50)) + (SUMIF('Df flex cabinet (2)'!$A$39:$A$50,A12,'Df flex cabinet (2)'!$G$39:$G$50)) + (SUMIF('Pole cover'!$A$33:$A$44,A12,'Pole cover'!$G$33:$G$44)) + (SUMIF('Pole cover (2)'!$A$33:$A$44,A12,'Pole cover (2)'!$G$33:$G$44)) + (SUMIF('Structural Steel Fab'!$A$33:$A$44,A12,'Structural Steel Fab'!$G$33:$G$44)) + (SUMIF(Reveal!$A$33:$A$44,A12,Reveal!$G$33:$G$44)) + (SUMIF('Reveal (2)'!$A$33:$A$44,A12,'Reveal (2)'!$G$33:$G$44)) + (SUMIF('Crown cove top'!$A$33:$A$44,A12,'Crown cove top'!$G$33:$G$44)) + (SUMIF('EMC assembly'!$A$33:$A$44,A12,'EMC assembly'!$G$33:$G$44)) + (SUMIF(Crating!$A$33:$A$44,A12,Crating!$G$33:$G$44)) + (SUMIF('LED wiring'!$A$33:$A$44,A12,'LED wiring'!$G$33:$G$44)) + (SUMIF('Changeable copy face'!$A$33:$A$44,A12,'Changeable copy face'!$G$33:$G$44)) + (SUMIF('Flex face assembly'!$A$33:$A$44,A12,'Flex face assembly'!$G$33:$G$44)) + (SUMIF('Routed face assembly'!$A$33:$A$44,A12,'Routed face assembly'!$G$33:$G$44)) + (SUMIF('Paint calculation'!$A$33:$A$44,A12,'Paint calculation'!$G$33:$G$44)) + (SUMIF('Trimcap letter face'!$A$33:$A$44,A12,'Trimcap letter face'!$G$33:$G$44)) + (SUMIF('Trimcap letter face (2)'!$A$33:$A$44,A12,'Trimcap letter face (2)'!$G$33:$G$44)) + (SUMIF('Channel letter fabrication'!$A$33:$A$44,A12,'Channel letter fabrication'!$G$33:$G$44)) + (SUMIF('Channel letter fabrication (2)'!$A$33:$A$44,A12,'Channel letter fabrication (2)'!$G$33:$G$44)) -> 19.25 | E12: =C12*D12 -> 1867.25
A13: 2114 | B13: Paint Vinyl Faces Labor | C13: =$B$3 -> 97 | D13: =(SUMIF('Freeform time and material'!$A$33:$A$44,A13,'Freeform time and material'!$G$33:$G$44)) + (SUMIF('Vinyl cutting'!$A$33:$A$44,A13,'Vinyl cutting'!$G$33:$G$44)) + (SUMIF('Vinyl cutting (2)'!$A$33:$A$44,A13,'Vinyl cutting (2)'!$G$33:$G$44)) + (SUMIF('Apply vinyl graphics'!$A$33:$A$44,A13,'Apply vinyl graphics'!$G$33:$G$44)) + (SUMIF('Apply vinyl graphics (2)'!$A$33:$A$44,A13,'Apply vinyl graphics (2)'!$G$33:$G$44)) + (SUMIF('Alum pan sign'!$A$33:$A$44,A13,'Alum pan sign'!$G$33:$G$44)) + (SUMIF('Alum pan sign (2)'!$A$33:$A$44,A13,'Alum pan sign (2)'!$G$33:$G$44)) + (SUMIF('Economy pan sign'!$A$33:$A$44,A13,'Economy pan sign'!$G$33:$G$44)) + (SUMIF('Post and panel sign'!$A$33:$A$44,A13,'Post and panel sign'!$G$33:$G$44)) + (SUMIF('Post and panel sign (2)'!$A$33:$A$44,A13,'Post and panel sign (2)'!$G$33:$G$44)) + (SUMIF('Flat panels only'!$A$33:$A$44,A13,'Flat panels only'!$G$33:$G$44)) + (SUMIF('Flat panels only (2)'!$A$33:$A$44,A13,'Flat panels only (2)'!$G$33:$G$44)) + (SUMIF('Routed panel shapes'!$A$34:$A$45,A13,'Routed panel shapes'!$G$34:$G$45)) + (SUMIF('Routed panel shapes (2)'!$A$34:$A$45,A13,'Routed panel shapes (2)'!$G$34:$G$45)) + (SUMIF('Routed face only'!$A$33:$A$44,A13,'Routed face only'!$G$33:$G$44)) + (SUMIF('Routed face only (2)'!$A$33:$A$44,A13,'Routed face only (2)'!$G$33:$G$44)) + (SUMIF('Routed alum faces letters'!$A$33:$A$44,A13,'Routed alum faces letters'!$G$33:$G$44)) + (SUMIF('Routed alum faces letters (2)'!$A$33:$A$44,A13,'Routed alum faces letters (2)'!$G$33:$G$44)) + (SUMIF('Routed push through acrylic'!$A$33:$A$44,A13,'Routed push through acrylic'!$G$33:$G$44)) + (SUMIF('Routed push through acrylic (2)'!$A$33:$A$44,A13,'Routed push through acrylic (2)'!$G$33:$G$44)) + (SUMIF('Sf routed cabinet'!$A$33:$A$44,A13,'Sf routed cabinet'!$G$33:$G$44)) + (SUMIF('Sf routed cabinet (2)'!$A$33:$A$44,A13,'Sf routed cabinet (2)'!$G$33:$G$44)) + (SUMIF('Df routed cabinet'!$A$33:$A$44,A13,'Df routed cabinet'!$G$33:$G$44)) + (SUMIF('Df routed cabinet (2)'!$A$33:$A$44,A13,'Df routed cabinet (2)'!$G$33:$G$44)) + (SUMIF('Sf acrylic cabinet'!$A$33:$A$44,A13,'Sf acrylic cabinet'!$G$33:$G$44)) + (SUMIF('Sf acrylic cabinet (2)'!$A$33:$A$44,A13,'Sf acrylic cabinet (2)'!$G$33:$G$44)) + (SUMIF('Economy Sf acrylic'!$A$33:$A$44,A13,'Economy Sf acrylic'!$G$33:$G$44)) + (SUMIF('Df acrylic cabinet'!$A$33:$A$44,A13,'Df acrylic cabinet'!$G$33:$G$44)) + (SUMIF('Df acrylic cabinet (2)'!$A$33:$A$44,A13,'Df acrylic cabinet (2)'!$G$33:$G$44)) + (SUMIF('Sf flex cabinet'!$A$33:$A$44,A13,'Sf flex cabinet'!$G$33:$G$44)) + (SUMIF('Sf flex cabinet (2)'!$A$33:$A$44,A13,'Sf flex cabinet (2)'!$G$33:$G$44)) + (SUMIF('Df flex cabinet'!$A$39:$A$50,A13,'Df flex cabinet'!$G$39:$G$50)) + (SUMIF('Df flex cabinet (2)'!$A$39:$A$50,A13,'Df flex cabinet (2)'!$G$39:$G$50)) + (SUMIF('Pole cover'!$A$33:$A$44,A13,'Pole cover'!$G$33:$G$44)) + (SUMIF('Pole cover (2)'!$A$33:$A$44,A13,'Pole cover (2)'!$G$33:$G$44)) + (SUMIF('Structural Steel Fab'!$A$33:$A$44,A13,'Structural Steel Fab'!$G$33:$G$44)) + (SUMIF(Reveal!$A$33:$A$44,A13,Reveal!$G$33:$G$44)) + (SUMIF('Reveal (2)'!$A$33:$A$44,A13,'Reveal (2)'!$G$33:$G$44)) + (SUMIF('Crown cove top'!$A$33:$A$44,A13,'Crown cove top'!$G$33:$G$44)) + (SUMIF('EMC assembly'!$A$33:$A$44,A13,'EMC assembly'!$G$33:$G$44)) + (SUMIF(Crating!$A$33:$A$44,A13,Crating!$G$33:$G$44)) + (SUMIF('LED wiring'!$A$33:$A$44,A13,'LED wiring'!$G$33:$G$44)) + (SUMIF('Changeable copy face'!$A$33:$A$44,A13,'Changeable copy face'!$G$33:$G$44)) + (SUMIF('Flex face assembly'!$A$33:$A$44,A13,'Flex face assembly'!$G$33:$G$44)) + (SUMIF('Routed face assembly'!$A$33:$A$44,A13,'Routed face assembly'!$G$33:$G$44)) + (SUMIF('Paint calculation'!$A$33:$A$44,A13,'Paint calculation'!$G$33:$G$44)) + (SUMIF('Trimcap letter face'!$A$33:$A$44,A13,'Trimcap letter face'!$G$33:$G$44)) + (SUMIF('Trimcap letter face (2)'!$A$33:$A$44,A13,'Trimcap letter face (2)'!$G$33:$G$44)) + (SUMIF('Channel letter fabrication'!$A$33:$A$44,A13,'Channel letter fabrication'!$G$33:$G$44)) + (SUMIF('Channel letter fabrication (2)'!$A$33:$A$44,A13,'Channel letter fabrication (2)'!$G$33:$G$44)) -> 0 | E13: =C13*D13 -> 0
A14: 2116 | B14: Hand Painting Labor | C14: =$B$3 -> 97 | D14: =(SUMIF('Freeform time and material'!$A$33:$A$44,A14,'Freeform time and material'!$G$33:$G$44)) + (SUMIF('Vinyl cutting'!$A$33:$A$44,A14,'Vinyl cutting'!$G$33:$G$44)) + (SUMIF('Vinyl cutting (2)'!$A$33:$A$44,A14,'Vinyl cutting (2)'!$G$33:$G$44)) + (SUMIF('Apply vinyl graphics'!$A$33:$A$44,A14,'Apply vinyl graphics'!$G$33:$G$44)) + (SUMIF('Apply vinyl graphics (2)'!$A$33:$A$44,A14,'Apply vinyl graphics (2)'!$G$33:$G$44)) + (SUMIF('Alum pan sign'!$A$33:$A$44,A14,'Alum pan sign'!$G$33:$G$44)) + (SUMIF('Alum pan sign (2)'!$A$33:$A$44,A14,'Alum pan sign (2)'!$G$33:$G$44)) + (SUMIF('Economy pan sign'!$A$33:$A$44,A14,'Economy pan sign'!$G$33:$G$44)) + (SUMIF('Post and panel sign'!$A$33:$A$44,A14,'Post and panel sign'!$G$33:$G$44)) + (SUMIF('Post and panel sign (2)'!$A$33:$A$44,A14,'Post and panel sign (2)'!$G$33:$G$44)) + (SUMIF('Flat panels only'!$A$33:$A$44,A14,'Flat panels only'!$G$33:$G$44)) + (SUMIF('Flat panels only (2)'!$A$33:$A$44,A14,'Flat panels only (2)'!$G$33:$G$44)) + (SUMIF('Routed panel shapes'!$A$34:$A$45,A14,'Routed panel shapes'!$G$34:$G$45)) + (SUMIF('Routed panel shapes (2)'!$A$34:$A$45,A14,'Routed panel shapes (2)'!$G$34:$G$45)) + (SUMIF('Routed face only'!$A$33:$A$44,A14,'Routed face only'!$G$33:$G$44)) + (SUMIF('Routed face only (2)'!$A$33:$A$44,A14,'Routed face only (2)'!$G$33:$G$44)) + (SUMIF('Routed alum faces letters'!$A$33:$A$44,A14,'Routed alum faces letters'!$G$33:$G$44)) + (SUMIF('Routed alum faces letters (2)'!$A$33:$A$44,A14,'Routed alum faces letters (2)'!$G$33:$G$44)) + (SUMIF('Routed push through acrylic'!$A$33:$A$44,A14,'Routed push through acrylic'!$G$33:$G$44)) + (SUMIF('Routed push through acrylic (2)'!$A$33:$A$44,A14,'Routed push through acrylic (2)'!$G$33:$G$44)) + (SUMIF('Sf routed cabinet'!$A$33:$A$44,A14,'Sf routed cabinet'!$G$33:$G$44)) + (SUMIF('Sf routed cabinet (2)'!$A$33:$A$44,A14,'Sf routed cabinet (2)'!$G$33:$G$44)) + (SUMIF('Df routed cabinet'!$A$33:$A$44,A14,'Df routed cabinet'!$G$33:$G$44)) + (SUMIF('Df routed cabinet (2)'!$A$33:$A$44,A14,'Df routed cabinet (2)'!$G$33:$G$44)) + (SUMIF('Sf acrylic cabinet'!$A$33:$A$44,A14,'Sf acrylic cabinet'!$G$33:$G$44)) + (SUMIF('Sf acrylic cabinet (2)'!$A$33:$A$44,A14,'Sf acrylic cabinet (2)'!$G$33:$G$44)) + (SUMIF('Economy Sf acrylic'!$A$33:$A$44,A14,'Economy Sf acrylic'!$G$33:$G$44)) + (SUMIF('Df acrylic cabinet'!$A$33:$A$44,A14,'Df acrylic cabinet'!$G$33:$G$44)) + (SUMIF('Df acrylic cabinet (2)'!$A$33:$A$44,A14,'Df acrylic cabinet (2)'!$G$33:$G$44)) + (SUMIF('Sf flex cabinet'!$A$33:$A$44,A14,'Sf flex cabinet'!$G$33:$G$44)) + (SUMIF('Sf flex cabinet (2)'!$A$33:$A$44,A14,'Sf flex cabinet (2)'!$G$33:$G$44)) + (SUMIF('Df flex cabinet'!$A$39:$A$50,A14,'Df flex cabinet'!$G$39:$G$50)) + (SUMIF('Df flex cabinet (2)'!$A$39:$A$50,A14,'Df flex cabinet (2)'!$G$39:$G$50)) + (SUMIF('Pole cover'!$A$33:$A$44,A14,'Pole cover'!$G$33:$G$44)) + (SUMIF('Pole cover (2)'!$A$33:$A$44,A14,'Pole cover (2)'!$G$33:$G$44)) + (SUMIF('Structural Steel Fab'!$A$33:$A$44,A14,'Structural Steel Fab'!$G$33:$G$44)) + (SUMIF(Reveal!$A$33:$A$44,A14,Reveal!$G$33:$G$44)) + (SUMIF('Reveal (2)'!$A$33:$A$44,A14,'Reveal (2)'!$G$33:$G$44)) + (SUMIF('Crown cove top'!$A$33:$A$44,A14,'Crown cove top'!$G$33:$G$44)) + (SUMIF('EMC assembly'!$A$33:$A$44,A14,'EMC assembly'!$G$33:$G$44)) + (SUMIF(Crating!$A$33:$A$44,A14,Crating!$G$33:$G$44)) + (SUMIF('LED wiring'!$A$33:$A$44,A14,'LED wiring'!$G$33:$G$44)) + (SUMIF('Changeable copy face'!$A$33:$A$44,A14,'Changeable copy face'!$G$33:$G$44)) + (SUMIF('Flex face assembly'!$A$33:$A$44,A14,'Flex face assembly'!$G$33:$G$44)) + (SUMIF('Routed face assembly'!$A$33:$A$44,A14,'Routed face assembly'!$G$33:$G$44)) + (SUMIF('Paint calculation'!$A$33:$A$44,A14,'Paint calculation'!$G$33:$G$44)) + (SUMIF('Trimcap letter face'!$A$33:$A$44,A14,'Trimcap letter face'!$G$33:$G$44)) + (SUMIF('Trimcap letter face (2)'!$A$33:$A$44,A14,'Trimcap letter face (2)'!$G$33:$G$44)) + (SUMIF('Channel letter fabrication'!$A$33:$A$44,A14,'Channel letter fabrication'!$G$33:$G$44)) + (SUMIF('Channel letter fabrication (2)'!$A$33:$A$44,A14,'Channel letter fabrication (2)'!$G$33:$G$44)) -> 2.5 | E14: =C14*D14 -> 242.5
A15: 2199 | B15: Rework Paint Labor | C15: =$B$3 -> 97 | D15: =(SUMIF('Freeform time and material'!$A$33:$A$44,A15,'Freeform time and material'!$G$33:$G$44)) + (SUMIF('Vinyl cutting'!$A$33:$A$44,A15,'Vinyl cutting'!$G$33:$G$44)) + (SUMIF('Vinyl cutting (2)'!$A$33:$A$44,A15,'Vinyl cutting (2)'!$G$33:$G$44)) + (SUMIF('Apply vinyl graphics'!$A$33:$A$44,A15,'Apply vinyl graphics'!$G$33:$G$44)) + (SUMIF('Apply vinyl graphics (2)'!$A$33:$A$44,A15,'Apply vinyl graphics (2)'!$G$33:$G$44)) + (SUMIF('Alum pan sign'!$A$33:$A$44,A15,'Alum pan sign'!$G$33:$G$44)) + (SUMIF('Alum pan sign (2)'!$A$33:$A$44,A15,'Alum pan sign (2)'!$G$33:$G$44)) + (SUMIF('Economy pan sign'!$A$33:$A$44,A15,'Economy pan sign'!$G$33:$G$44)) + (SUMIF('Post and panel sign'!$A$33:$A$44,A15,'Post and panel sign'!$G$33:$G$44)) + (SUMIF('Post and panel sign (2)'!$A$33:$A$44,A15,'Post and panel sign (2)'!$G$33:$G$44)) + (SUMIF('Flat panels only'!$A$33:$A$44,A15,'Flat panels only'!$G$33:$G$44)) + (SUMIF('Flat panels only (2)'!$A$33:$A$44,A15,'Flat panels only (2)'!$G$33:$G$44)) + (SUMIF('Routed panel shapes'!$A$34:$A$45,A15,'Routed panel shapes'!$G$34:$G$45)) + (SUMIF('Routed panel shapes (2)'!$A$34:$A$45,A15,'Routed panel shapes (2)'!$G$34:$G$45)) + (SUMIF('Routed face only'!$A$33:$A$44,A15,'Routed face only'!$G$33:$G$44)) + (SUMIF('Routed face only (2)'!$A$33:$A$44,A15,'Routed face only (2)'!$G$33:$G$44)) + (SUMIF('Routed alum faces letters'!$A$33:$A$44,A15,'Routed alum faces letters'!$G$33:$G$44)) + (SUMIF('Routed alum faces letters (2)'!$A$33:$A$44,A15,'Routed alum faces letters (2)'!$G$33:$G$44)) + (SUMIF('Routed push through acrylic'!$A$33:$A$44,A15,'Routed push through acrylic'!$G$33:$G$44)) + (SUMIF('Routed push through acrylic (2)'!$A$33:$A$44,A15,'Routed push through acrylic (2)'!$G$33:$G$44)) + (SUMIF('Sf routed cabinet'!$A$33:$A$44,A15,'Sf routed cabinet'!$G$33:$G$44)) + (SUMIF('Sf routed cabinet (2)'!$A$33:$A$44,A15,'Sf routed cabinet (2)'!$G$33:$G$44)) + (SUMIF('Df routed cabinet'!$A$33:$A$44,A15,'Df routed cabinet'!$G$33:$G$44)) + (SUMIF('Df routed cabinet (2)'!$A$33:$A$44,A15,'Df routed cabinet (2)'!$G$33:$G$44)) + (SUMIF('Sf acrylic cabinet'!$A$33:$A$44,A15,'Sf acrylic cabinet'!$G$33:$G$44)) + (SUMIF('Sf acrylic cabinet (2)'!$A$33:$A$44,A15,'Sf acrylic cabinet (2)'!$G$33:$G$44)) + (SUMIF('Economy Sf acrylic'!$A$33:$A$44,A15,'Economy Sf acrylic'!$G$33:$G$44)) + (SUMIF('Df acrylic cabinet'!$A$33:$A$44,A15,'Df acrylic cabinet'!$G$33:$G$44)) + (SUMIF('Df acrylic cabinet (2)'!$A$33:$A$44,A15,'Df acrylic cabinet (2)'!$G$33:$G$44)) + (SUMIF('Sf flex cabinet'!$A$33:$A$44,A15,'Sf flex cabinet'!$G$33:$G$44)) + (SUMIF('Sf flex cabinet (2)'!$A$33:$A$44,A15,'Sf flex cabinet (2)'!$G$33:$G$44)) + (SUMIF('Df flex cabinet'!$A$39:$A$50,A15,'Df flex cabinet'!$G$39:$G$50)) + (SUMIF('Df flex cabinet (2)'!$A$39:$A$50,A15,'Df flex cabinet (2)'!$G$39:$G$50)) + (SUMIF('Pole cover'!$A$33:$A$44,A15,'Pole cover'!$G$33:$G$44)) + (SUMIF('Pole cover (2)'!$A$33:$A$44,A15,'Pole cover (2)'!$G$33:$G$44)) + (SUMIF('Structural Steel Fab'!$A$33:$A$44,A15,'Structural Steel Fab'!$G$33:$G$44)) + (SUMIF(Reveal!$A$33:$A$44,A15,Reveal!$G$33:$G$44)) + (SUMIF('Reveal (2)'!$A$33:$A$44,A15,'Reveal (2)'!$G$33:$G$44)) + (SUMIF('Crown cove top'!$A$33:$A$44,A15,'Crown cove top'!$G$33:$G$44)) + (SUMIF('EMC assembly'!$A$33:$A$44,A15,'EMC assembly'!$G$33:$G$44)) + (SUMIF(Crating!$A$33:$A$44,A15,Crating!$G$33:$G$44)) + (SUMIF('LED wiring'!$A$33:$A$44,A15,'LED wiring'!$G$33:$G$44)) + (SUMIF('Changeable copy face'!$A$33:$A$44,A15,'Changeable copy face'!$G$33:$G$44)) + (SUMIF('Flex face assembly'!$A$33:$A$44,A15,'Flex face assembly'!$G$33:$G$44)) + (SUMIF('Routed face assembly'!$A$33:$A$44,A15,'Routed face assembly'!$G$33:$G$44)) + (SUMIF('Paint calculation'!$A$33:$A$44,A15,'Paint calculation'!$G$33:$G$44)) + (SUMIF('Trimcap letter face'!$A$33:$A$44,A15,'Trimcap letter face'!$G$33:$G$44)) + (SUMIF('Trimcap letter face (2)'!$A$33:$A$44,A15,'Trimcap letter face (2)'!$G$33:$G$44)) + (SUMIF('Channel letter fabrication'!$A$33:$A$44,A15,'Channel letter fabrication'!$G$33:$G$44)) + (SUMIF('Channel letter fabrication (2)'!$A$33:$A$44,A15,'Channel letter fabrication (2)'!$G$33:$G$44)) -> 0 | E15: =C15*D15 -> 0
A16: 2212 | B16: LED Wiring Labor | C16: =$B$3 -> 97 | D16: =(SUMIF('Freeform time and material'!$A$33:$A$44,A16,'Freeform time and material'!$G$33:$G$44)) + (SUMIF('Vinyl cutting'!$A$33:$A$44,A16,'Vinyl cutting'!$G$33:$G$44)) + (SUMIF('Vinyl cutting (2)'!$A$33:$A$44,A16,'Vinyl cutting (2)'!$G$33:$G$44)) + (SUMIF('Apply vinyl graphics'!$A$33:$A$44,A16,'Apply vinyl graphics'!$G$33:$G$44)) + (SUMIF('Apply vinyl graphics (2)'!$A$33:$A$44,A16,'Apply vinyl graphics (2)'!$G$33:$G$44)) + (SUMIF('Alum pan sign'!$A$33:$A$44,A16,'Alum pan sign'!$G$33:$G$44)) + (SUMIF('Alum pan sign (2)'!$A$33:$A$44,A16,'Alum pan sign (2)'!$G$33:$G$44)) + (SUMIF('Economy pan sign'!$A$33:$A$44,A16,'Economy pan sign'!$G$33:$G$44)) + (SUMIF('Post and panel sign'!$A$33:$A$44,A16,'Post and panel sign'!$G$33:$G$44)) + (SUMIF('Post and panel sign (2)'!$A$33:$A$44,A16,'Post and panel sign (2)'!$G$33:$G$44)) + (SUMIF('Flat panels only'!$A$33:$A$44,A16,'Flat panels only'!$G$33:$G$44)) + (SUMIF('Flat panels only (2)'!$A$33:$A$44,A16,'Flat panels only (2)'!$G$33:$G$44)) + (SUMIF('Routed panel shapes'!$A$34:$A$45,A16,'Routed panel shapes'!$G$34:$G$45)) + (SUMIF('Routed panel shapes (2)'!$A$34:$A$45,A16,'Routed panel shapes (2)'!$G$34:$G$45)) + (SUMIF('Routed face only'!$A$33:$A$44,A16,'Routed face only'!$G$33:$G$44)) + (SUMIF('Routed face only (2)'!$A$33:$A$44,A16,'Routed face only (2)'!$G$33:$G$44)) + (SUMIF('Routed alum faces letters'!$A$33:$A$44,A16,'Routed alum faces letters'!$G$33:$G$44)) + (SUMIF('Routed alum faces letters (2)'!$A$33:$A$44,A16,'Routed alum faces letters (2)'!$G$33:$G$44)) + (SUMIF('Routed push through acrylic'!$A$33:$A$44,A16,'Routed push through acrylic'!$G$33:$G$44)) + (SUMIF('Routed push through acrylic (2)'!$A$33:$A$44,A16,'Routed push through acrylic (2)'!$G$33:$G$44)) + (SUMIF('Sf routed cabinet'!$A$33:$A$44,A16,'Sf routed cabinet'!$G$33:$G$44)) + (SUMIF('Sf routed cabinet (2)'!$A$33:$A$44,A16,'Sf routed cabinet (2)'!$G$33:$G$44)) + (SUMIF('Df routed cabinet'!$A$33:$A$44,A16,'Df routed cabinet'!$G$33:$G$44)) + (SUMIF('Df routed cabinet (2)'!$A$33:$A$44,A16,'Df routed cabinet (2)'!$G$33:$G$44)) + (SUMIF('Sf acrylic cabinet'!$A$33:$A$44,A16,'Sf acrylic cabinet'!$G$33:$G$44)) + (SUMIF('Sf acrylic cabinet (2)'!$A$33:$A$44,A16,'Sf acrylic cabinet (2)'!$G$33:$G$44)) + (SUMIF('Economy Sf acrylic'!$A$33:$A$44,A16,'Economy Sf acrylic'!$G$33:$G$44)) + (SUMIF('Df acrylic cabinet'!$A$33:$A$44,A16,'Df acrylic cabinet'!$G$33:$G$44)) + (SUMIF('Df acrylic cabinet (2)'!$A$33:$A$44,A16,'Df acrylic cabinet (2)'!$G$33:$G$44)) + (SUMIF('Sf flex cabinet'!$A$33:$A$44,A16,'Sf flex cabinet'!$G$33:$G$44)) + (SUMIF('Sf flex cabinet (2)'!$A$33:$A$44,A16,'Sf flex cabinet (2)'!$G$33:$G$44)) + (SUMIF('Df flex cabinet'!$A$39:$A$50,A16,'Df flex cabinet'!$G$39:$G$50)) + (SUMIF('Df flex cabinet (2)'!$A$39:$A$50,A16,'Df flex cabinet (2)'!$G$39:$G$50)) + (SUMIF('Pole cover'!$A$33:$A$44,A16,'Pole cover'!$G$33:$G$44)) + (SUMIF('Pole cover (2)'!$A$33:$A$44,A16,'Pole cover (2)'!$G$33:$G$44)) + (SUMIF('Structural Steel Fab'!$A$33:$A$44,A16,'Structural Steel Fab'!$G$33:$G$44)) + (SUMIF(Reveal!$A$33:$A$44,A16,Reveal!$G$33:$G$44)) + (SUMIF('Reveal (2)'!$A$33:$A$44,A16,'Reveal (2)'!$G$33:$G$44)) + (SUMIF('Crown cove top'!$A$33:$A$44,A16,'Crown cove top'!$G$33:$G$44)) + (SUMIF('EMC assembly'!$A$33:$A$44,A16,'EMC assembly'!$G$33:$G$44)) + (SUMIF(Crating!$A$33:$A$44,A16,Crating!$G$33:$G$44)) + (SUMIF('LED wiring'!$A$33:$A$44,A16,'LED wiring'!$G$33:$G$44)) + (SUMIF('Changeable copy face'!$A$33:$A$44,A16,'Changeable copy face'!$G$33:$G$44)) + (SUMIF('Flex face assembly'!$A$33:$A$44,A16,'Flex face assembly'!$G$33:$G$44)) + (SUMIF('Routed face assembly'!$A$33:$A$44,A16,'Routed face assembly'!$G$33:$G$44)) + (SUMIF('Paint calculation'!$A$33:$A$44,A16,'Paint calculation'!$G$33:$G$44)) + (SUMIF('Trimcap letter face'!$A$33:$A$44,A16,'Trimcap letter face'!$G$33:$G$44)) + (SUMIF('Trimcap letter face (2)'!$A$33:$A$44,A16,'Trimcap letter face (2)'!$G$33:$G$44)) + (SUMIF('Channel letter fabrication'!$A$33:$A$44,A16,'Channel letter fabrication'!$G$33:$G$44)) + (SUMIF('Channel letter fabrication (2)'!$A$33:$A$44,A16,'Channel letter fabrication (2)'!$G$33:$G$44)) -> 7.25 | E16: =C16*D16 -> 703.25
A17: 2215 | B17: Assembly Labor | C17: =$B$3 -> 97 | D17: =(SUMIF('Freeform time and material'!$A$33:$A$44,A17,'Freeform time and material'!$G$33:$G$44)) + (SUMIF('Vinyl cutting'!$A$33:$A$44,A17,'Vinyl cutting'!$G$33:$G$44)) + (SUMIF('Vinyl cutting (2)'!$A$33:$A$44,A17,'Vinyl cutting (2)'!$G$33:$G$44)) + (SUMIF('Apply vinyl graphics'!$A$33:$A$44,A17,'Apply vinyl graphics'!$G$33:$G$44)) + (SUMIF('Apply vinyl graphics (2)'!$A$33:$A$44,A17,'Apply vinyl graphics (2)'!$G$33:$G$44)) + (SUMIF('Alum pan sign'!$A$33:$A$44,A17,'Alum pan sign'!$G$33:$G$44)) + (SUMIF('Alum pan sign (2)'!$A$33:$A$44,A17,'Alum pan sign (2)'!$G$33:$G$44)) + (SUMIF('Economy pan sign'!$A$33:$A$44,A17,'Economy pan sign'!$G$33:$G$44)) + (SUMIF('Post and panel sign'!$A$33:$A$44,A17,'Post and panel sign'!$G$33:$G$44)) + (SUMIF('Post and panel sign (2)'!$A$33:$A$44,A17,'Post and panel sign (2)'!$G$33:$G$44)) + (SUMIF('Flat panels only'!$A$33:$A$44,A17,'Flat panels only'!$G$33:$G$44)) + (SUMIF('Flat panels only (2)'!$A$33:$A$44,A17,'Flat panels only (2)'!$G$33:$G$44)) + (SUMIF('Routed panel shapes'!$A$34:$A$45,A17,'Routed panel shapes'!$G$34:$G$45)) + (SUMIF('Routed panel shapes (2)'!$A$34:$A$45,A17,'Routed panel shapes (2)'!$G$34:$G$45)) + (SUMIF('Routed face only'!$A$33:$A$44,A17,'Routed face only'!$G$33:$G$44)) + (SUMIF('Routed face only (2)'!$A$33:$A$44,A17,'Routed face only (2)'!$G$33:$G$44)) + (SUMIF('Routed alum faces letters'!$A$33:$A$44,A17,'Routed alum faces letters'!$G$33:$G$44)) + (SUMIF('Routed alum faces letters (2)'!$A$33:$A$44,A17,'Routed alum faces letters (2)'!$G$33:$G$44)) + (SUMIF('Routed push through acrylic'!$A$33:$A$44,A17,'Routed push through acrylic'!$G$33:$G$44)) + (SUMIF('Routed push through acrylic (2)'!$A$33:$A$44,A17,'Routed push through acrylic (2)'!$G$33:$G$44)) + (SUMIF('Sf routed cabinet'!$A$33:$A$44,A17,'Sf routed cabinet'!$G$33:$G$44)) + (SUMIF('Sf routed cabinet (2)'!$A$33:$A$44,A17,'Sf routed cabinet (2)'!$G$33:$G$44)) + (SUMIF('Df routed cabinet'!$A$33:$A$44,A17,'Df routed cabinet'!$G$33:$G$44)) + (SUMIF('Df routed cabinet (2)'!$A$33:$A$44,A17,'Df routed cabinet (2)'!$G$33:$G$44)) + (SUMIF('Sf acrylic cabinet'!$A$33:$A$44,A17,'Sf acrylic cabinet'!$G$33:$G$44)) + (SUMIF('Sf acrylic cabinet (2)'!$A$33:$A$44,A17,'Sf acrylic cabinet (2)'!$G$33:$G$44)) + (SUMIF('Economy Sf acrylic'!$A$33:$A$44,A17,'Economy Sf acrylic'!$G$33:$G$44)) + (SUMIF('Df acrylic cabinet'!$A$33:$A$44,A17,'Df acrylic cabinet'!$G$33:$G$44)) + (SUMIF('Df acrylic cabinet (2)'!$A$33:$A$44,A17,'Df acrylic cabinet (2)'!$G$33:$G$44)) + (SUMIF('Sf flex cabinet'!$A$33:$A$44,A17,'Sf flex cabinet'!$G$33:$G$44)) + (SUMIF('Sf flex cabinet (2)'!$A$33:$A$44,A17,'Sf flex cabinet (2)'!$G$33:$G$44)) + (SUMIF('Df flex cabinet'!$A$39:$A$50,A17,'Df flex cabinet'!$G$39:$G$50)) + (SUMIF('Df flex cabinet (2)'!$A$39:$A$50,A17,'Df flex cabinet (2)'!$G$39:$G$50)) + (SUMIF('Pole cover'!$A$33:$A$44,A17,'Pole cover'!$G$33:$G$44)) + (SUMIF('Pole cover (2)'!$A$33:$A$44,A17,'Pole cover (2)'!$G$33:$G$44)) + (SUMIF('Structural Steel Fab'!$A$33:$A$44,A17,'Structural Steel Fab'!$G$33:$G$44)) + (SUMIF(Reveal!$A$33:$A$44,A17,Reveal!$G$33:$G$44)) + (SUMIF('Reveal (2)'!$A$33:$A$44,A17,'Reveal (2)'!$G$33:$G$44)) + (SUMIF('Crown cove top'!$A$33:$A$44,A17,'Crown cove top'!$G$33:$G$44)) + (SUMIF('EMC assembly'!$A$33:$A$44,A17,'EMC assembly'!$G$33:$G$44)) + (SUMIF(Crating!$A$33:$A$44,A17,Crating!$G$33:$G$44)) + (SUMIF('LED wiring'!$A$33:$A$44,A17,'LED wiring'!$G$33:$G$44)) + (SUMIF('Changeable copy face'!$A$33:$A$44,A17,'Changeable copy face'!$G$33:$G$44)) + (SUMIF('Flex face assembly'!$A$33:$A$44,A17,'Flex face assembly'!$G$33:$G$44)) + (SUMIF('Routed face assembly'!$A$33:$A$44,A17,'Routed face assembly'!$G$33:$G$44)) + (SUMIF('Paint calculation'!$A$33:$A$44,A17,'Paint calculation'!$G$33:$G$44)) + (SUMIF('Trimcap letter face'!$A$33:$A$44,A17,'Trimcap letter face'!$G$33:$G$44)) + (SUMIF('Trimcap letter face (2)'!$A$33:$A$44,A17,'Trimcap letter face (2)'!$G$33:$G$44)) + (SUMIF('Channel letter fabrication'!$A$33:$A$44,A17,'Channel letter fabrication'!$G$33:$G$44)) + (SUMIF('Channel letter fabrication (2)'!$A$33:$A$44,A17,'Channel letter fabrication (2)'!$G$33:$G$44)) -> 18.75 | E17: =C17*D17 -> 1818.75
... A30: 2499 | B30: Rework Graphics Labor | C30: =$B$3 -> 97 | D30: =(SUMIF('Freeform time and material'!$A$33:$A$44,A30,'Freeform time and material'!$G$33:$G$44)) + (SUMIF('Vinyl cutting'!$A$33:$A$44,A30,'Vinyl cutting'!$G$33:$G$44)) + (SUMIF('Vinyl cutting (2)'!$A$33:$A$44,A30,'Vinyl cutting (2)'!$G$33:$G$44)) + (SUMIF('Apply vinyl graphics'!$A$33:$A$44,A30,'Apply vinyl graphics'!$G$33:$G$44)) + (SUMIF('Apply vinyl graphics (2)'!$A$33:$A$44,A30,'Apply vinyl graphics (2)'!$G$33:$G$44)) + (SUMIF('Alum pan sign'!$A$33:$A$44,A30,'Alum pan sign'!$G$33:$G$44)) + (SUMIF('Alum pan sign (2)'!$A$33:$A$44,A30,'Alum pan sign (2)'!$G$33:$G$44)) + (SUMIF('Economy pan sign'!$A$33:$A$44,A30,'Economy pan sign'!$G$33:$G$44)) + (SUMIF('Post and panel sign'!$A$33:$A$44,A30,'Post and panel sign'!$G$33:$G$44)) + (SUMIF('Post and panel sign (2)'!$A$33:$A$44,A30,'Post and panel sign (2)'!$G$33:$G$44)) + (SUMIF('Flat panels only'!$A$33:$A$44,A30,'Flat panels only'!$G$33:$G$44)) + (SUMIF('Flat panels only (2)'!$A$33:$A$44,A30,'Flat panels only (2)'!$G$33:$G$44)) + (SUMIF('Routed panel shapes'!$A$34:$A$45,A30,'Routed panel shapes'!$G$34:$G$45)) + (SUMIF('Routed panel shapes (2)'!$A$34:$A$45,A30,'Routed panel shapes (2)'!$G$34:$G$45)) + (SUMIF('Routed face only'!$A$33:$A$44,A30,'Routed face only'!$G$33:$G$44)) + (SUMIF('Routed face only (2)'!$A$33:$A$44,A30,'Routed face only (2)'!$G$33:$G$44)) + (SUMIF('Routed alum faces letters'!$A$33:$A$44,A30,'Routed alum faces letters'!$G$33:$G$44)) + (SUMIF('Routed alum faces letters (2)'!$A$33:$A$44,A30,'Routed alum faces letters (2)'!$G$33:$G$44)) + (SUMIF('Routed push through acrylic'!$A$33:$A$44,A30,'Routed push through acrylic'!$G$33:$G$44)) + (SUMIF('Routed push through acrylic (2)'!$A$33:$A$44,A30,'Routed push through acrylic (2)'!$G$33:$G$44)) + (SUMIF('Sf routed cabinet'!$A$33:$A$44,A30,'Sf routed cabinet'!$G$33:$G$44)) + (SUMIF('Sf routed cabinet (2)'!$A$33:$A$44,A30,'Sf routed cabinet (2)'!$G$33:$G$44)) + (SUMIF('Df routed cabinet'!$A$33:$A$44,A30,'Df routed cabinet'!$G$33:$G$44)) + (SUMIF('Df routed cabinet (2)'!$A$33:$A$44,A30,'Df routed cabinet (2)'!$G$33:$G$44)) + (SUMIF('Sf acrylic cabinet'!$A$33:$A$44,A30,'Sf acrylic cabinet'!$G$33:$G$44)) + (SUMIF('Sf acrylic cabinet (2)'!$A$33:$A$44,A30,'Sf acrylic cabinet (2)'!$G$33:$G$44)) + (SUMIF('Economy Sf acrylic'!$A$33:$A$44,A30,'Economy Sf acrylic'!$G$33:$G$44)) + (SUMIF('Df acrylic cabinet'!$A$33:$A$44,A30,'Df acrylic cabinet'!$G$33:$G$44)) + (SUMIF('Df acrylic cabinet (2)'!$A$33:$A$44,A30,'Df acrylic cabinet (2)'!$G$33:$G$44)) + (SUMIF('Sf flex cabinet'!$A$33:$A$44,A30,'Sf flex cabinet'!$G$33:$G$44)) + (SUMIF('Sf flex cabinet (2)'!$A$33:$A$44,A30,'Sf flex cabinet (2)'!$G$33:$G$44)) + (SUMIF('Df flex cabinet'!$A$39:$A$50,A30,'Df flex cabinet'!$G$39:$G$50)) + (SUMIF('Df flex cabinet (2)'!$A$39:$A$50,A30,'Df flex cabinet (2)'!$G$39:$G$50)) + (SUMIF('Pole cover'!$A$33:$A$44,A30,'Pole cover'!$G$33:$G$44)) + (SUMIF('Pole cover (2)'!$A$33:$A$44,A30,'Pole cover (2)'!$G$33:$G$44)) + (SUMIF('Structural Steel Fab'!$A$33:$A$44,A30,'Structural Steel Fab'!$G$33:$G$44)) + (SUMIF(Reveal!$A$33:$A$44,A30,Reveal!$G$33:$G$44)) + (SUMIF('Reveal (2)'!$A$33:$A$44,A30,'Reveal (2)'!$G$33:$G$44)) + (SUMIF('Crown cove top'!$A$33:$A$44,A30,'Crown cove top'!$G$33:$G$44)) + (SUMIF('EMC assembly'!$A$33:$A$44,A30,'EMC assembly'!$G$33:$G$44)) + (SUMIF(Crating!$A$33:$A$44,A30,Crating!$G$33:$G$44)) + (SUMIF('LED wiring'!$A$33:$A$44,A30,'LED wiring'!$G$33:$G$44)) + (SUMIF('Changeable copy face'!$A$33:$A$44,A30,'Changeable copy face'!$G$33:$G$44)) + (SUMIF('Flex face assembly'!$A$33:$A$44,A30,'Flex face assembly'!$G$33:$G$44)) + (SUMIF('Routed face assembly'!$A$33:$A$44,A30,'Routed face assembly'!$G$33:$G$44)) + (SUMIF('Paint calculation'!$A$33:$A$44,A30,'Paint calculation'!$G$33:$G$44)) + (SUMIF('Trimcap letter face'!$A$33:$A$44,A30,'Trimcap letter face'!$G$33:$G$44)) + (SUMIF('Trimcap letter face (2)'!$A$33:$A$44,A30,'Trimcap letter face (2)'!$G$33:$G$44)) + (SUMIF('Channel letter fabrication'!$A$33:$A$44,A30,'Channel letter fabrication'!$G$33:$G$44)) + (SUMIF('Channel letter fabrication (2)'!$A$33:$A$44,A30,'Channel letter fabrication (2)'!$G$33:$G$44)) -> 0 | E30: =C30*D30 -> 0
D31: =SUM(D6:D30) -> 179.3125 | E31: =SUM(E6:E30) -> 17393.312

Sheet Inv
A1: Description | B1: No. | C1: Unit Cost | D1: Unit Price | E1: Base Unit of Measure | F1: Profit % | G1: Piece Length (Ft) | H1: Last Date of Purchase | I1: Job Number | J1: Total Estimated Units
A3: =[1]ODBC!$A3 -> SHOP SUPPLIES | B3: =[1]ODBC!B3 -> 0 | C3: =IFERROR(VLOOKUP($B3,[1]ODBC!$B:$H,2,FALSE),"") -> 1 | D3: =IFERROR(VLOOKUP($B3,[1]ODBC!$B:$H,3,FALSE),"") -> 1 | E3: =IFERROR(VLOOKUP($B3,[1]ODBC!$B:$H,4,FALSE),"") -> EA | F3: =IFERROR(VLOOKUP($B3,[1]ODBC!$B:$H,5,FALSE),"") -> 0 | G3: =[1]ODBC!G3 -> 0 | H3: =SUM([1]ODBC!H3) -> 45964 | I3: ='Vinyl cutting'!$B$2 -> J36938 | J3: =(SUMIF('Freeform time and material'!$B$17:$B$30,B3,'Freeform time and material'!$G$17:$G$30)) + (SUMIF('Vinyl cutting'!$B$17:$B$30,B3,'Vinyl cutting'!$G$17:$G$30)) + (SUMIF('Vinyl cutting (2)'!$B$17:$B$30,B3,'Vinyl cutting (2)'!$G$17:$G$30)) + (SUMIF('Apply vinyl graphics'!$B$17:$B$30,B3,'Apply vinyl graphics'!$G$17:$G$30)) + (SUMIF('Apply vinyl graphics (2)'!$B$17:$B$30,B3,'Apply vinyl graphics (2)'!$G$17:$G$30)) + (SUMIF('Alum pan sign'!$B$17:$B$30,B3,'Alum pan sign'!$G$17:$G$30)) + (SUMIF('Alum pan sign (2)'!$B$17:$B$30,B3,'Alum pan sign (2)'!$G$17:$G$30)) + (SUMIF('Economy pan sign'!$B$17:$B$30,B3,'Economy pan sign'!$G$17:$G$30)) + (SUMIF('Post and panel sign'!$B$17:$B$30,B3,'Post and panel sign'!$G$17:$G$30)) + (SUMIF('Post and panel sign (2)'!$B$17:$B$30,B3,'Post and panel sign (2)'!$G$17:$G$30)) + (SUMIF('Flat panels only'!$B$17:$B$30,B3,'Flat panels only'!$G$17:$G$30)) + (SUMIF('Flat panels only (2)'!$B$17:$B$30,B3,'Flat panels only (2)'!$G$17:$G$30)) + (SUMIF('Routed panel shapes'!$B$18:$B$31,B3,'Routed panel shapes'!$G$18:$G$31)) + (SUMIF('Routed panel shapes (2)'!$B$18:$B$31,B3,'Routed panel shapes (2)'!$G$18:$G$31)) + (SUMIF('Routed face only'!$B$17:$B$30,B3,'Routed face only'!$G$17:$G$30)) + (SUMIF('Routed face only (2)'!$B$17:$B$30,B3,'Routed face only (2)'!$G$17:$G$30)) + (SUMIF('Routed alum faces letters'!$B$17:$B$30,B3,'Routed alum faces letters'!$G$17:$G$30)) + (SUMIF('Routed alum faces letters (2)'!$B$17:$B$30,B3,'Routed alum faces letters (2)'!$G$17:$G$30)) + (SUMIF('Routed push through acrylic'!$B$17:$B$30,B3,'Routed push through acrylic'!$G$17:$G$30)) + (SUMIF('Routed push through acrylic (2)'!$B$17:$B$30,B3,'Routed push through acrylic (2)'!$G$17:$G$30)) + (SUMIF('Sf routed cabinet'!$B$17:$B$30,B3,'Sf routed cabinet'!$G$17:$G$30)) + (SUMIF('Sf routed cabinet (2)'!$B$17:$B$30,B3,'Sf routed cabinet (2)'!$G$17:$G$30)) + (SUMIF('Df routed cabinet'!$B$17:$B$30,B3,'Df routed cabinet'!$G$17:$G$30)) + (SUMIF('Df routed cabinet (2)'!$B$17:$B$30,B3,'Df routed cabinet (2)'!$G$17:$G$30)) + (SUMIF('Sf acrylic cabinet'!$B$17:$B$30,B3,'Sf acrylic cabinet'!$G$17:$G$30)) + (SUMIF('Sf acrylic cabinet (2)'!$B$17:$B$30,B3,'Sf acrylic cabinet (2)'!$G$17:$G$30)) + (SUMIF('Economy Sf acrylic'!$B$17:$B$30,B3,'Economy Sf acrylic'!$G$17:$G$30)) + (SUMIF('Df acrylic cabinet'!$B$17:$B$30,B3,'Df acrylic cabinet'!$G$17:$G$30)) + (SUMIF('Df acrylic cabinet (2)'!$B$17:$B$30,B3,'Df acrylic cabinet (2)'!$G$17:$G$30)) + (SUMIF('Sf flex cabinet'!$B$17:$B$30,B3,'Sf flex cabinet'!$G$17:$G$30)) + (SUMIF('Sf flex cabinet (2)'!$B$17:$B$30,B3,'Sf flex cabinet (2)'!$G$17:$G$30)) + (SUMIF('Df flex cabinet'!$B$17:$B$36,B3,'Df flex cabinet'!$G$17:$G$36)) + (SUMIF('Df flex cabinet (2)'!$B$17:$B$36,B3,'Df flex cabinet (2)'!$G$17:$G$36)) + (SUMIF('Pole cover'!$B$17:$B$30,B3,'Pole cover'!$G$17:$G$30)) + (SUMIF('Pole cover (2)'!$B$17:$B$30,B3,'Pole cover (2)'!$G$17:$G$30)) + (SUMIF('Structural Steel Fab'!$B$17:$B$29,B3,'Structural Steel Fab'!$G$17:$G$29)) + (SUMIF(Reveal!$B$17:$B$30,B3,Reveal!$G$17:$G$30)) + (SUMIF('Reveal (2)'!$B$17:$B$30,B3,'Reveal (2)'!$G$17:$G$30)) + (SUMIF('Crown cove top'!$B$17:$B$30,B3,'Crown cove top'!$G$17:$G$30)) + (SUMIF('EMC assembly'!$B$17:$B$30,B3,'EMC assembly'!$G$17:$G$30)) + (SUMIF(Crating!$B$17:$B$29,B3,Crating!$G$17:$G$29)) + (SUMIF('LED wiring'!$B$17:$B$30,B3,'LED wiring'!$G$17:$G$30)) + (SUMIF('Changeable copy face'!$B$17:$B$30,B3,'Changeable copy face'!$G$17:$G$30)) + (SUMIF('Flex face assembly'!$B$17:$B$30,B3,'Flex face assembly'!$G$17:$G$30)) + (SUMIF('Routed face assembly'!$B$17:$B$30,B3,'Routed face assembly'!$G$17:$G$30)) + (SUMIF('Paint calculation'!$B$17:$B$30,B3,'Paint calculation'!$G$17:$G$30)) + (SUMIF('Trimcap letter face'!$B$17:$B$30,B3,'Trimcap letter face'!$G$17:$G$30)) + (SUMIF('Trimcap letter face (2)'!$B$17:$B$30,B3,'Trimcap letter face (2)'!$G$17:$G$30)) + (SUMIF('Channel letter fabrication'!$B$17:$B$30,B3,'Channel letter fabrication'!$G$17:$G$30)) + (SUMIF('Channel letter fabrication (2)'!$B$17:$B$30,B3,'Channel letter fabrication (2)'!$G$17:$G$30)) -> 0
